<?xml version="1.0"?>
 <robot xmlns:xacro="http://www.ros.org/wiki/xacro">
  <xacro:macro name="robot_hand" params="prefix">
    <link name="${prefix}_hand">
      <visual>
        <geometry>
          <mesh filename="package://tm_grasp_description/meshes/hand/visual/hand.dae"/>
        </geometry>
      </visual>
      <collision>
        <geometry>
          <mesh filename="package://tm_grasp_description/meshes/hand/collision/hand.stl"/>
        </geometry>
      </collision>
    </link>
    <link name="${prefix}_leftfinger">
      <visual>
        <geometry>
          <mesh filename="package://tm_grasp_description/meshes/hand/visual/finger.dae"/>
        </geometry>
      </visual>
      <collision>
        <geometry>
          <mesh filename="package://tm_grasp_description/meshes/hand/collision/finger.stl"/>
        </geometry>
      </collision>
    </link>
    <link name="${prefix}_rightfinger">
      <visual>
        <origin xyz="0 0 0" rpy="0 0 ${pi}"/>
        <geometry>
          <mesh filename="package://tm_grasp_description/meshes/hand/visual/finger.dae"/>
        </geometry>
      </visual>
      <collision>
        <origin xyz="0 0 0" rpy="0 0 ${pi}"/>
        <geometry>
          <mesh filename="package://tm_grasp_description/meshes/hand/collision/finger.stl"/>
        </geometry>
      </collision>
    </link>



  <!--up is hand link-->
   <!-- bleow is hand joint-->

   <joint name="${prefix}_hand_joint" type="fixed">
      <parent link="${prefix}tip_link"/>
      <child link="${prefix}_hand"/>
      <origin xyz="0 0 0" rpy="0 0 ${pi/2}"/>
      <axis xyz="0 0 0}"/>
    </joint>

    <joint name="${prefix}_finger_joint1" type="prismatic">
      <parent link="${prefix}_hand"/>
      <child link="${prefix}_leftfinger"/>
      <origin xyz="0 0 0.0584" rpy="0 0 0"/>
      <axis xyz="0 1 0"/>
      <limit effort="20" lower="0.0" upper="0.04" velocity="0.2"/>
    </joint>
    <joint name="${prefix}_finger_joint2" type="prismatic">
      <parent link="${prefix}_hand"/>
      <child link="${prefix}_rightfinger"/>
      <origin xyz="0 0 0.0584" rpy="0 0 0"/>
      <axis xyz="0 -1 0"/>
      <limit effort="20" lower="0.0" upper="0.04" velocity="0.2"/>
      <mimic joint="${prefix}_finger_joint1" />
    </joint>


    <!-- end is hand joint-->
  </xacro:macro>
 </robot>

